Workbook
Name \C: #REF!
Name \D: #REF!
Name _1_5digit: #REF!
Name _Q09: #REF!
Name a: [6]ISICrev3.1!$E:$F
Name AA: #REF!
Name aaa: #REF!
Name AAAAAA: #REF!
Name B: #REF!
Name Base: '[7]LCO - Inputs'!$A$70
Name bvdp: #REF!
Name bvdpin: #REF!
Name Calculated_Relationship_HS12___HS07: '[8]Correlation HS2012-HS2007'!#REF!
Name ccc: #REF!
Name com_desc: [9]com_desc!$A$1:$B$96
Name consol: #REF!
Name consolID: #REF!
Name desc: #REF!
Name desc_frm180: [10]desc_frm180!$A$2:$C$181
Name desc_frm92: [11]desc_frm92!$A$2:$B$94
Name ER: #REF!
Name export_prt: #REF!
Name f: #REF!
Name FRAMEIND: #REF!
Name FRAMEIND2: #REF!
Name frm: #REF!
Name frm_com: #REF!
Name frm_ind: #REF!
Name frm180_desc: [10]desc_frm180!$B$2:$C$181
Name frm92_nita: [13]MSIC!$A$1:$C$10782
Name G_prt: #REF!
Name GDPIO: #REF!
Name GDPUPDT: #REF!
Name GFCF_prt: #REF!
Name gg: #REF!
Name go_level_top1: OFFSET('[14]35-sector'!$E$36,MATCH(#REF!,'[14]35-sector'!$E$37:$E$71,0),2,1,8)
Name govt: [15]frmind92!$C$178:$D$235
Name hh: #REF!
Name HH_prt: #REF!
Name HS: '[16]HS02_CPC1.1_SITC3_ISIC3.1 (2)'!#REF!
Name ID_prt: #REF!
Name in: #REF!
Name ind: #REF!
Name INP: [17]MSIC!$A$1:$C$10782
Name input: #REF!
Name io: #REF!
Name IO_Code: #REF!
Name IO_Code2: #REF!
Name iocom: #REF!
Name kol: #REF!
Name Large: '[7]LCO - Inputs'!$A$71
Name M1_stone: '[14]2000'!$E$1382:$BV$1451
Name M2_stone: '[14]2000'!$E$1524:$BV$1593
Name M3_stone: '[14]2000'!$E$1737:$BV$1806
Name makebv: #REF!
Name makect: #REF!
Name makeout: #REF!
Name Malaysia_curr_pub: #REF!
Name Malaysia_FD_Source_Curr: #REF!
Name Matrix1: #REF!

Sheet COVER
B7: SAF & CORSIA DEMAND PROJECTION MODEL
B8: ="Model Name: "&MID(CELL("filename"),FIND("[",CELL("filename"))+1,FIND("]",CELL("filename"))-FIND("[",CELL("filename"))-1) -> Model Name: SAF_CORSIA_Demand_Model_v2.3.xlsx | G8: =TODAY() -> 46191
B9: Purpose | C9: Bottom-up demand modelling and scenario building for jet fuel and SAF from different regions
B10: Version | C10: 2.3
B11: Developed by | C11: Hammad Ainuddin
B12: Reviewed by | C12: David Toh
B13: Approved by
B16: Description
B17: This model provides a route-level, bottom-up analysis of jet fuel demand, CO₂ emissions, SAF (Sustainable Aviation Fuel) mandate obligations, and CORSIA carbon offset requirements for 1,274 international routes operated by 160 airlines across all major world regions. Six SAF demand scenarios (A&M Base, A&M Policy-Driven, A&M Climate Push, IATA Reference, Top-Down Policy, Top-Down Accelerated) are projected from 2025 to 2050. All parameters are centralised in the INPUTS (including SCENARIOS) sheet and propagate automatically to calculation and summary sheets.
B26: Document control
B28: Version | C28: Revision notes | D28: Revision date | E28: Authors
B29: v2.3 | C29: Refine scenario parameters, UN Stats country value and mapping misalignments in the Routes sheet | D29: 46189 | E29: HA
B30: v2.2 | C30: Develop A&M Scenarios, refine spreadsheet flow-structure and remove redundant tabs | D30: 46183 | E30: HA
B31: v2.1 | C31: Detailed review on routes and aligment with UN Stats (International Aviation Bunker) | D31: 46177 | E31: HA
B32: v2 | C32: Expansion of routes to include missing airlines and routes (from 64 to ~1274 routes) | D32: 46176 | E32: HA
B33: v1 | C33: Initial draft prepared | D33: 46157 | E33: HA
B36: MODEL SCOPE
B37: 1260 | C37: Flight Routes | D37: International trunk routes across 6 world regions, operated by major carriers in all scenarios
B38: 160 | C38: Operators | D38: 135 passenger airlines, 13 freighter airlines, 2 cargo integrators, 5 ACMI/charter, 5 other
B39: 14 | C39: Aircraft Types | D39: Narrowbody, widebody, large widebody and freighter variants
B40: 40 | C40: Data Sources | D40: ICAO, IATA, OAG, IEA, Airbus, Boeing, regulatory texts
B41: 4 | C41: A&M SAF Scenarios | D41: A&M Base, A&M Policy-Driven, A&M Climate Push, IATA Reference
B42: 2 | C42: Top-down SAF Scenarios | D42: Policy (mandates), Accelerated (1.5°C)
B43: 2025–2050 | C43: Projection Horizon | D43: Annual granularity 2025–2030; milestone years to 2050
B45: WORKBOOK STRUCTURE
B46: Type | C46: Sheet Name | D46: Description
B47: COVER | C47: COVER | D47: This sheet — model description, structure, and legend
B48: INPUT | C48: ▌ INPUT ▌ | D48: Divider — all sheets below are input / reference data
B49: INPUT | C49: INPUTS | D49: All model parameters: constants, growth rates, SAF mandates, scenarios
B50: INPUT | C50: OPERATORS | D50: Airline and cargo operator registry (160 operators)
B51: INPUT | C51: AIRCRAFT | D51: Aircraft performance lookup table (14 types)
B52: CALC | C52: ▌ CALC ▌ | D52: Divider — all sheets below are calculation sheets
B53: CALC | C53: ROUTES | D53: Route-level fuel, CO₂ and SAF calculations (1274 routes)
B54: CALC | C54: SUMMARY | D54: Comparison between different SAF% blend scenarios (2025–2040)
B57: CELL COLOUR LEGEND
B58: Colour | C58: Name | D58: Colour Name | E58: Description
B59: ■ | C59: INPUT cell | D59: Yellow | E59: User-editable parameter. Safe to modify. Located primarily in INPUTS sheet.
B60: ■ | C60: CALC cell | D60: Blue | E60: Formula-driven calculation. Do NOT edit manually — will be overwritten.
B61: ■ | C61: OUTPUT cell | D61: Green | E61: Final result or derived metric. Reads from CALC sheets.
B62: ■ | C62: LINK cell | D62: Peach | E62: Cross-sheet reference (=SheetName!CellRef). Formula-derived; do not edit.
...

Sheet ▌ INPUT ▌
A1: INPUT

Sheet INPUTS
A1: INPUTS — All Model Parameters & Lookup Tables | Yellow = user-editable | Blue = formula-derived
A2: Editing values in this sheet automatically updates ROUTES, REGIONAL, CORSIA, SAF_DEMAND, and SUMMARY. Do NOT edit cells coloured blue (formula-derived). All monetary values in USD.
A4: A AVIATION CONSTANTS
A5: Parameter | B5: Value | C5: Unit | D5: Source | E5: Notes
A6: CO₂ Emission Factor — Jet A-1 | B6: 3.16 | C6: t CO₂ / t fuel | D6: IPCC AR6 / ICAO Annex 16 | E6: Standard factor; used in all route CO₂ calcs
A7: Jet A-1 Fuel Density | B7: 0.8 | C7: kg/L (t/m³) | D7: ASTM D1655 | E7: Used to convert mass (t) → volume (kL)
A8: Average Pax Load Factor | B8: 0.82 | C8: fraction | D8: IATA 2024 Annual Review | E8: Used for seat-based fuel benchmarking
A9: Average Cargo Mass Load Factor | B9: 0.72 | C9: fraction | D9: IATA/Boeing WACF 2024 | E9: Typical freighter payload utilisation
A10: CORSIA Intl Route Fraction | B10: 0.85 | C10: fraction | D10: ICAO A41-22 | E10: % of aviation emissions from international routes
A11: Global Efficiency Improvement | B11: -0.013 | C11: %/yr | D11: IATA/ATAG net-zero roadmap | E11: Fleet renewal + ATM; negative = improvement
A13: B CORSIA FRAMEWORK PARAMETERS
A14: Parameter | B14: Value | C14: Unit | D14: Source | E14: Notes
A15: Global Intl Aviation CO₂ — 2019 (actual) | B15: 359.4 | C15: Mt CO₂ | D15: ICAO Annual Report 2022 | E15: Pre-pandemic baseline reference year
A16: CORSIA Baseline Factor | B16: 0.85 | C16: fraction | D16: ICAO Assembly Resolution A41-22 | E16: Revised 2022: 85% of 2019 emissions
A17: CORSIA Baseline Emissions | B17: =B15*B16 -> 305.49 | C17: Mt CO₂ | D17: INPUTS calculated | E17: Auto-calculated: 2019 actual × baseline factor
A18: Global Intl CO₂ — 2025 Estimate | B18: 900 | C18: Mt CO₂ | D18: ICAO/IATA 2025 forecast | E18: Post-recovery trajectory
A19: CORSIA Phase 1 Start Year | B19: 2024 | C19: year | D19: ICAO A41-22 | E19: Voluntary phase
A20: CORSIA Phase 1 End Year | B20: 2026 | C20: year | D20: ICAO A41-22
A21: CORSIA Phase 2 Start Year | B21: 2027 | C21: year | D21: ICAO A41-22 | E21: Mandatory for all participating states
A22: CORSIA Phase 2 End Year | B22: 2035 | C22: year | D22: ICAO A41-22
A23: Phase 1 Route Coverage (% of intl routes) | B23: 0.8 | C23: fraction | D23: 126 CORSIA participating states | E23: Routes where both endpoints participate
A24: Phase 2 Route Coverage (% of intl routes) | B24: 0.95 | C24: fraction | D24: ICAO mandatory expansion | E24: Excludes LDC/SIDS/LLDC exemptions
A26: C CARBON CREDIT PRICES — CORSIA EEUs ($/t CO₂e)
A27: Phase | B27: Period | C27: Low ($/t) | D27: Mid ($/t) | E27: High ($/t)
A28: Phase 1 | B28: 2024–2026 | C28: 18 | D28: 35 | E28: 51
A29: Phase 2 | B29: 2027–2035 | C29: 27 | D29: 60 | E29: 91
A30: Post-2035 | B30: 2036–2050 | C30: 100 | D30: 150 | E30: 200
A32: D TRAFFIC GROWTH RATES — Net (pa, after efficiency) by Origin Region
A33: Origin Region | B33: Net Growth Rate (pa) | C33: Basis / Source | D33: CORSIA P1 Scope Note | F33: Notes
A34: EU | B34: 0.025 | C34: ICAO/OAG European Aviation Outlook | D34: All intl EU-state routes P1 eligible; ReFuelEU mandate applies | F34: Net of 1.3%/yr efficiency gain
A35: US | B35: 0.02 | C35: FAA Aerospace Forecast FY2024 | D35: All US intl routes P1 eligible; US domestic excluded | F35: Mature market; lower growth
A36: APAC | B36: 0.04 | C36: IATA APAC Growth Outlook 2024 | D36: P1 eligible if dest≠CN/IN/VN; JP/KR/AU/NZ/SG/MY/TH/PH/ID all participate | F36: Fastest growing region
A37: MENA | B37: 0.045 | C37: IATA GCC Aviation Outlook | D37: All GCC states P1 eligible | F37: Hub expansion; high growth
A38: LATAM | B38: 0.035 | C38: IATA Latin America Forecast | D38: P1 eligible excl. BR origin/dest; Colombia/Chile/Peru/Ecuador/Mexico all P1 | F38: Recovery + emerging markets
A39: ROW | B39: 0.03 | C39: ICAO/IATA blended forecast | D39: Excl. RU; most African states P1 eligible | F39: Mixed market maturity
A41: E SAF MANDATE % — Airport-Level Lookup (ROUTES cols Y & AA reference this table)
A42: VLOOKUP key: Origin Airport Code (ROUTES col E). Returns SAF blend % for 2025 and 2030. Airports not listed → formula returns 0% (no mandate).
A43: Origin Airport (IATA) | B43: SAF% 2025 | C43: SAF% 2030 | D43: SAF% 2035 | E43: SAF% 2040 | F43: SAF% 2045 | G43: SAF% 2050 | H43: Mandate Basis | I43: Regulatory Reference
A44: FRA | B44: 0.02 | C44: 0.06 | D44: 0.15 | E44: 0.3 | F44: 0.4 | G44: 0.5 | H44: EU – ReFuelEU | I44: Reg (EU) 2023/2405
A45: CDG | B45: 0.02 | C45: 0.06 | D45: 0.15 | E45: 0.3 | F45: 0.4 | G45: 0.5 | H45: EU – ReFuelEU | I45: Reg (EU) 2023/2405
...

Sheet AIRCRAFT
A1: AIRCRAFT TYPE DATABASE — Fuel Efficiency Reference Table
A3: Aircraft Type | B3: Fuel Efficiency (t/km total) | C3: Category | D3: Typical Capacity (pax / t cargo) | E3: Typical Range (km) | F3: Notes / Applications
A4: A320neo | B4: 0.0039 | C4: Narrowbody | D4: 150 | E4: 3500 | F4: Narrow body short-medium haul
A5: A321neo | B5: 0.0042 | C5: Widebody | D5: 300 | E5: 12000 | F5: Narrow body medium haul
A6: B737-800 | B6: 0.0041 | C6: Narrowbody | D6: 150 | E6: 3500 | F6: Narrow body short-medium haul
A7: B737MAX8 | B7: 0.0039 | C7: Narrowbody | D7: 150 | E7: 3500 | F7: Narrow body short-medium haul
A8: A330-300 | B8: 0.0085 | C8: Widebody | D8: 300 | E8: 12000 | F8: Wide body medium-long haul
A9: B787-9 | B9: 0.0079 | C9: Widebody | D9: 300 | E9: 12000 | F9: Wide body long haul
A10: A350-900 | B10: 0.0079 | C10: Widebody | D10: 300 | E10: 12000 | F10: Wide body long haul
A11: B777-300ER | B11: 0.0089 | C11: Widebody | D11: 300 | E11: 12000 | F11: Wide body long haul
A12: A380-800 | B12: 0.0105 | C12: Widebody | D12: 555 | E12: 12000 | F12: Very large wide body
A13: B747-8 | B13: 0.01 | C13: Widebody | D13: 300 | E13: 12000 | F13: Very large wide body
A14: B777F | B14: 0.0082 | C14: Large widebody cargo freighter | D14: Cargo | E14: 102000 | F14: 9200
A15: B747-8F | B15: 0.0096 | C15: Very large widebody cargo freighter | D15: Cargo | E15: 137800 | F15: 8130
A16: B757F | B16: 0.0046 | C16: Medium narrowbody cargo freighter | D16: Cargo | E16: 22680 | F16: 5850
A17: B767F | B17: 0.0068 | C17: Medium-large widebody cargo freighter | D17: Cargo | E17: 52163 | F17: 6025
A20: ▌ FUEL EFFICIENCY NOTES
A21: • Fuel efficiency expressed as total fuel burn per km (all passengers + freight + aircraft weight).
A22: • Source: ICAO Aircraft Engine Emissions Databank, manufacturer fuel burn data, IATA Economics.
A23: • Cargo freighters (B777F, B747-8F) include fuel per km for typical payload; actual efficiency varies with load factor.
A24: • Efficiency improvements of 1.2-1.5%/yr expected through fleet renewal — see ASSUMPTIONS sheet.
A25: • CO₂ factor: multiply fuel (tonnes) × 3.16 to get CO₂ equivalent tonnes.

Sheet OPERATORS
A1: OPERATORS DATABASE — Passenger Airlines & Cargo Operators Subject to CORSIA / SAF Mandates
A3: ID | B3: Operator Name | C3: Home Country | D3: Region | E3: Hub IATA | F3: Hub Country | G3: Hub Region | H3: Operator Type | I3: Fleet Size | J3: Ownership Model | K3: CORSIA Liability | L3: CORSIA Phase 1 | M3: CORSIA Phase 2
A4: LH | B4: Lufthansa | C4: Germany | D4: EU | E4: FRA | F4: Germany | G4: EU | H4: Passenger Airline | I4: N/A | J4: Direct Owned | K4: CORSIA Direct Liable | L4: Yes | M4: Yes
A5: AF | B5: Air France | C5: France | D5: EU | E5: CDG | F5: France | G5: EU | H5: Passenger Airline | I5: N/A | J5: Direct Owned | K5: CORSIA Direct Liable | L5: Yes | M5: Yes
A6: BA | B6: British Airways | C6: UK | D6: EU | E6: LHR | F6: UK | G6: EU | H6: Passenger Airline | I6: N/A | J6: Direct Owned | K6: CORSIA Direct Liable | L6: Yes | M6: Yes
A7: KL | B7: KLM | C7: Netherlands | D7: EU | E7: AMS | F7: Netherlands | G7: EU | H7: Passenger Airline | I7: N/A | J7: Direct Owned | K7: CORSIA Direct Liable | L7: Yes | M7: Yes
A8: IB | B8: Iberia | C8: Spain | D8: EU | E8: MAD | F8: Spain | G8: EU | H8: Passenger Airline | I8: N/A | J8: Direct Owned | K8: CORSIA Direct Liable | L8: Yes | M8: Yes
A9: UA | B9: United Airlines | C9: USA | D9: US | E9: EWR | F9: USA | G9: US | H9: Passenger Airline | I9: N/A | J9: Direct Owned | K9: CORSIA Direct Liable | L9: Yes | M9: Yes
A10: AA | B10: American Airlines | C10: USA | D10: US | E10: DFW | F10: USA | G10: US | H10: Passenger Airline | I10: N/A | J10: Direct Owned | K10: CORSIA Direct Liable | L10: Yes | M10: Yes
A11: DL | B11: Delta Air Lines | C11: USA | D11: US | E11: ATL | F11: USA | G11: US | H11: Passenger Airline | I11: N/A | J11: Direct Owned | K11: CORSIA Direct Liable | L11: Yes | M11: Yes
A12: WN | B12: Southwest Airlines | C12: USA | D12: US | E12: DAL | F12: USA | G12: US | H12: Passenger Airline | I12: N/A | J12: Direct Owned | K12: CORSIA Direct Liable | L12: Yes | M12: Yes
A13: SQ | B13: Singapore Airlines | C13: Singapore | D13: APAC | E13: SIN | F13: Singapore | G13: APAC | H13: Passenger Airline | I13: N/A | J13: Direct Owned | K13: CORSIA Direct Liable | L13: Yes | M13: Yes
A14: NH | B14: ANA | C14: Japan | D14: APAC | E14: NRT | F14: Japan | G14: APAC | H14: Passenger Airline | I14: N/A | J14: Direct Owned | K14: CORSIA Direct Liable | L14: Yes | M14: Yes
... A23: TK | B23: Turkish Airlines | C23: Turkey | D23: ROW | E23: IST | F23: Turkey | G23: ROW | H23: Passenger Airline | I23: N/A | J23: Direct Owned | K23: CORSIA Direct Liable | L23: Yes | M23: Yes
A24: FX | B24: FedEx Express | C24: USA | D24: US | E24: MEM | F24: USA | G24: US | H24: Cargo Integrator | I24: 700 | J24: Direct Owned | K24: CORSIA Direct Liable | L24: Yes | M24: Yes
A25: 5X | B25: UPS Airlines | C25: USA | D25: US | E25: SDF | F25: USA | G25: US | H25: Cargo Integrator | I25: 291 | J25: Direct Owned | K25: CORSIA Direct Liable | L25: Yes | M25: Yes
A26: D0 | B26: DHL Aviation | C26: Germany | D26: EU | E26: CGN | F26: Germany | G26: EU | H26: Hybrid/ACMI | I26: 310 | J26: ACMI Partner | K26: CORSIA via AOC Holder | L26: Yes | M26: Yes
A27: K9 | B27: Amazon Air | C27: USA | D27: US | E27: CVG | F27: USA | G27: US | H27: E-Commerce/ACMI | I27: 90 | J27: Wet Lease | K27: CORSIA via Operator AOC | L27: Yes | M27: Yes
A28: 5Y | B28: Atlas Air | C28: USA | D28: US | E28: JFK | F28: USA | G28: US | H28: ACMI Provider | I28: 93 | J28: ACMI Lessor | K28: CORSIA Direct (Operator) | L28: Yes | M28: Yes
A29: K4 | B29: Kalitta Air | C29: USA | D29: US | E29: YIP | F29: USA | G29: US | H29: ACMI Charter | I29: 40 | J29: ACMI Lessor | K29: CORSIA Direct (Operator) | L29: Yes | M29: Yes
A30: ABR | B30: ASL Aviation Holdings | C30: Ireland | D30: EU | E30: DUB | F30: Ireland | G30: EU | H30: ACMI Provider | I30: 150 | J30: ACMI Lessor | K30: CORSIA Direct (Operator) | L30: Yes | M30: Yes
A31: CV | B31: Cargolux | C31: Luxembourg | D31: EU | E31: LUX | F31: Luxembourg | G31: EU | H31: Freighter Airline | I31: 30 | J31: Direct Owned | K31: CORSIA Direct Liable | L31: Yes | M31: Yes
A32: LHC | B32: Lufthansa Cargo | C32: Germany | D32: EU | E32: FRA | F32: Germany | G32: EU | H32: Freighter Airline | I32: 20 | J32: Direct Owned | K32: CORSIA Direct Liable | L32: Yes | M32: Yes
A33: QRC | B33: Qatar Airways Cargo | C33: Qatar | D33: MENA | E33: DOH | F33: Qatar | G33: MENA | H33: Freighter Airline | I33: 30 | J33: Direct Owned | K33: CORSIA Direct Liable | L33: Yes | M33: Yes
A34: EKC | B34: Emirates SkyCargo | C34: UAE | D34: MENA | E34: DXB | F34: UAE | G34: MENA | H34: Freighter Airline | I34: 11 | J34: Direct Owned | K34: CORSIA Direct Liable | L34: Yes | M34: Yes
A35: KE | B35: Korean Air | C35: South Korea | D35: APAC | E35: ICN | F35: South Korea | G35: APAC | H35: Freighter Airline | I35: 20 | J35: Direct Owned | K35: CORSIA Direct Liable | L35: Yes | M35: Yes
... A166: FV | B166: Rossiya Airlines | C166: Russia | D166: ROW | E166: LED | F166: Russia | G166: ROW | H166: Passenger Airline | I166: 65 | J166: Direct Owned | K166: CORSIA Direct Liable | L166: No | M166: Yes
A169: ▌ CORSIA APPLICABILITY NOTES & DEFINITIONS
A170: CORSIA Direct Liable | E170: Operator holds AOC; ICAO designator filed in Box 7 of flight plan. Full MRV + offsetting obligation applies.
A171: CORSIA via AOC Holder | E171: ACMI model: legal liability sits with the contracted operator (AOC holder). Economic cost passed through via contractual clauses.
A172: CORSIA via Operator AOC | E172: Wet-lease arrangement: logistics brand (e.g. Amazon) is NOT liable; ACMI operator (e.g. Atlas Air) holds CORSIA liability.
A173: Exempt - LDC | E173: Least Developed Country exemption per ICAO Assembly Resolution A41-22 (Annex to Resolution). MRV still required.
A174: Partial | E174: Route/state-level applicability varies. Phase 1: routes between non-participating state pairs are exempt.

Sheet SCENARIOS
A1: SCENARIO BUILDING SHEET
A3: Case Description | B3: C1 - A&M base case | C3: C2 - A&M policy-driven | D3: C3 - A&M climate push | E3: C4 - IATA reference | G3: to have option for the adjustment on the fuel efficiency
A4: Growth rate cases consideration | B4: EU: 2.5% US: 2.0% APAC: 4.0% MENA: 4.5% LATAM: 3.5% ROW: 3.0% | C4: EU: 2.5% US: 2.0% APAC: 4.0% MENA: 4.5% LATAM: 3.5% ROW: 3.0% | D4: EU: 2.5% US: 2.0% APAC: 4.0% MENA: 4.5% LATAM: 3.5% ROW: 3.0% | E4: EU: 3.0% US: 2.5% APAC: 5.0% MENA: 4.5% LATAM: 4.0% ROW: 3.5% | J4: Fuel efficiency is expressed in tonnes of fuel per kilometre for the whole aircraft (not per seat). Each route is assigned an aircraft type from this table, and the base efficiency is multiplied by an annual improvement factor: Eff(year) = Eff₂₀₂₅ × (1 − 0.015)^(year − 2025) The 1.5% per annum improvement rate reflects average fleet-level efficiency gains from new-generation aircraft (A320neo, A350, B787) entering service and retiring older frames. This rate can be adjusted here to test more aggressive or conservative technology scenarios. Heavier widebody aircraft (A380, B777) have lower efficiency per km in absolute terms but typically serve longer routes, so their contribution to total fuel burn depends heavily on route distance.
A5: Blending target % | B5: The most conservative scenario. Based on demand driven by states/regions with existing SAF blending mandate and targets | C5: The central scenario. Based on demand driven by states/regions with existing SAF blending mandate and targets, and international airlines reporting to CORSIA | D5: The 'high' scenario considering higher % of SAF blending than the A&M Policy-Driven Scenario for airlines with no currently binding targets | E5: IATA case is considered the most ambitious scenario pushing for high level of decarbonisation for the international aviation sector, targeting ~57% SAF consumption from total jet fuel by 2050. A&M has assumed ~50% SAF out of total international aviation jet fuel by 2050
A6: Fuel efficiency cases consideration | B6: No efficiency improvement | C6: 1.5% efficiency improvement every year | D6: 2.0% efficiency improvement every year | E6: No efficiency improvement
A7: Willingness to pay | B7: EU: 2600-3200 through 2050 US: 1500-2200 through 2050 APAC: 1300-1800 through 2050 MENA: 1000-1300 through 2050 | C7: EU: 2800-3600 through 2050 US: 1700-2400 through 2050 APAC: 1500-2000 through 2050 MENA: 1100-1400 through 2050 | D7: EU: 3000-4000 through 2050 US: 1700-2500 through 2050 APAC: 1600-2200 through 2050 MENA: 1200-1600 through 2050 | E7: EU: 3000-4000 through 2050 US: 1700-2500 through 2050 APAC: 1600-2200 through 2050 MENA: 1200-1600 through 2050
A8: Carbon pricing | B8: 2025: 30 USD 2050: 190 USD | C8: 2025: 30 USD 2050: 250 USD | D8: 2025: 30 USD 2050: 300 USD | E8: 2025: 30 USD 2050: 300 USD
A10: TRAFFIC GROWTH RATES — Net (pa, after efficiency) by Origin Region
A11: Scenarios | B11: C1 - A&M base case | C11: C2 - A&M policy-driven | D11: C3 - A&M climate push | E11: C4 - IATA reference | H11: reference
A12: Origin Region | B12: Net Growth Rate (pa) | C12: Net Growth Rate (pa) | D12: Net Growth Rate (pa) | E12: Net Growth Rate (pa) | H12: ~420 Mt in 2050
A13: EU | B13: 0.025 | C13: 0.025 | D13: 0.025 | E13: 0.03 | H13: 0.03
A14: US | B14: 0.02 | C14: 0.02 | D14: 0.02 | E14: 0.025 | H14: 0.025
A15: APAC | B15: 0.04 | C15: 0.04 | D15: 0.04 | E15: 0.05 | H15: 0.05
A16: MENA | B16: 0.045 | C16: 0.045 | D16: 0.045 | E16: 0.045 | H16: 0.045
A17: LATAM | B17: 0.035 | C17: 0.035 | D17: 0.035 | E17: 0.04 | H17: 0.04
A18: ROW | B18: 0.03 | C18: 0.03 | D18: 0.03 | E18: 0.035 | H18: 0.035
A20: SAF MANDATE % — Airport-Level Lookup (ROUTES cols Y & AA reference this table)
A21: VLOOKUP key: Origin Airport Code (ROUTES col E). Returns SAF blend % for 2025, 2030, 2035, 2040, 2045, 2050 | J21: Airports not listed → formula returns the values below
A22: Origin Airport (IATA) | B22: SAF% 2025 | C22: SAF% 2030 | D22: SAF% 2035 | E22: SAF% 2040 | F22: SAF% 2045 | G22: SAF% 2050 | J22: SAF% 2030 | K22: SAF% 2035 | L22: SAF% 2040 | M22: SAF% 2045 | N22: SAF% 2050
A23: FRA | B23: 0.02 | C23: 0.06 | D23: 0.15 | E23: 0.3 | F23: 0.4 | G23: 0.5 | I23: C1 - A&M base case | J23: 0 | K23: 0 | L23: 0 | M23: 0 | N23: 0
A24: CDG | B24: 0.02 | C24: 0.06 | D24: 0.15 | E24: 0.3 | F24: 0.4 | G24: 0.5 | I24: C2 - A&M policy-driven | J24: 0.01 | K24: 0.05 | L24: 0.1 | M24: 0.2 | N24: 0.25
A25: AMS | B25: 0.02 | C25: 0.06 | D25: 0.15 | E25: 0.3 | F25: 0.4 | G25: 0.5 | I25: C3 - A&M climate push | J25: 0.015 | K25: 0.075 | L25: 0.15 | M25: 0.2 | N25: 0.3
A26: MAD | B26: 0.02 | C26: 0.06 | D26: 0.15 | E26: 0.3 | F26: 0.4 | G26: 0.5 | I26: C4 - IATA reference | J26: 0.025 | K26: 0.1 | L26: 0.2 | M26: 0.3 | N26: 0.5
A27: BCN | B27: 0.02 | C27: 0.06 | D27: 0.15 | E27: 0.3 | F27: 0.4 | G27: 0.5
A28: FCO | B28: 0.02 | C28: 0.06 | D28: 0.15 | E28: 0.3 | F28: 0.4 | G28: 0.5
A29: MUC | B29: 0.02 | C29: 0.06 | D29: 0.15 | E29: 0.3 | F29: 0.4 | G29: 0.5
A30: ZRH | B30: 0.02 | C30: 0.06 | D30: 0.15 | E30: 0.3 | F30: 0.4 | G30: 0.5
A31: VIE | B31: 0.02 | C31: 0.06 | D31: 0.15 | E31: 0.3 | F31: 0.4 | G31: 0.5
A32: CPH | B32: 0.02 | C32: 0.06 | D32: 0.15 | E32: 0.3 | F32: 0.4 | G32: 0.5
A33: HEL | B33: 0.02 | C33: 0.06 | D33: 0.15 | E33: 0.3 | F33: 0.4 | G33: 0.5
A34: LIS | B34: 0.02 | C34: 0.06 | D34: 0.15 | E34: 0.3 | F34: 0.4 | G34: 0.5
A35: OSL | B35: 0.02 | C35: 0.06 | D35: 0.15 | E35: 0.3 | F35: 0.4 | G35: 0.5
A36: DUB | B36: 0.02 | C36: 0.06 | D36: 0.15 | E36: 0.3 | F36: 0.4 | G36: 0.5
A37: BUD | B37: 0.02 | C37: 0.06 | D37: 0.15 | E37: 0.3 | F37: 0.4 | G37: 0.5
A38: ORY | B38: 0.02 | C38: 0.06 | D38: 0.15 | E38: 0.3 | F38: 0.4 | G38: 0.5
... A82: AKL | B82: 0 | C82: 0.02 | D82: 0.05 | E82: 0.15 | F82: 0.2 | G82: 0.3
A84: Fuel efficiency improvement (Annual % improvement)
A85: Scenarios | B85: C1 - A&M base case | C85: C2 - A&M policy-driven | D85: C3 - A&M climate push | E85: C4 - IATA reference
B86: % Improvement (pa) | C86: % Improvement (pa) | D86: % Improvement (pa) | E86: % Improvement (pa)
A87: Fleet level improvement | B87: 0 | C87: 0.0025 | D87: 0.005 | E87: 0.025
...

Sheet ▌ CALC ▌
A1: CALC

Sheet Test
A1: FLIGHT ROUTES DATABASE — Comprehensive Route-Level Fuel & CORSIA/SAF Analysis | 242 Routes (64 Passenger original + 53 Cargo + 125 Expanded Passenger)
AB2: 5 | AD2: 10 | AF2: 15 | AH2: 20 | AJ2: 25 | AT2: SAF in tonnes per annum - Region | BC2: SAF in tonnes per annum - Airport | BM2: SAF in tonnes per annum - Country
A3: Route ID | B3: Airline ID | C3: Operator Name | D3: Segment (Pax/Cargo) | E3: Origin Airport | F3: Origin Country | G3: Origin Region | H3: Dest Airport | I3: Dest Country | J3: Dest Region | K3: Flight Category | L3: Aircraft Type | M3: Annual Flights 2025 | N3: Trips per Day | O3: Distance (km/trip) | P3: km Flown per Year | Q3: Growth Rate | R3: Fuel Eff. (t/km) | S3: Fuel per Trip (t) | T3: Fuel per Year 2025 (t) | U3: Fuel per Year 2025 (L) | V3: CO₂ per Year 2025 (t) | W3: CORSIA Phase 1 | X3: CORSIA Phase 2 | Y3: SAF% 2025 | Z3: SAF Demand 2025 (t) | AA3: SAF% 2030 | AB3: SAF Demand 2030 (t) | AC3: SAF% 2035 | AD3: SAF Demand 2035 (t) | AE3: SAF% 2040 | AF3: SAF Demand 2040 (t) | AG3: SAF% 2045 | AH3: SAF Demand 2045 (t) | AI3: SAF% 2050 | AJ3: SAF Demand 2050 (t) | AL3: Reciprocal in DB? | AM3: 2050 Global Jet Fuel demand | AU3: 2025 | AV3: 2030 | AW3: 2035 | AX3: 2040 | AY3: 2045 | AZ3: 2050 | BD3: 2025 | BE3: 2030 | BF3: 2035 | BG3: 2040 | BH3: 2045 | BI3: 2050 | BN3: 2025 | BO3: 2030 | BP3: 2035 | BQ3: 2040 | BR3: 2045 | BS3: 2050
A4: R001 | B4: LH | C4: Lufthansa | D4: Passenger | E4: FRA | F4: Germany | G4: EU | H4: JFK | I4: United States | J4: US | K4: international | L4: A350-900 | M4: 730 | N4: =M4/365 -> 2 | O4: 6200 | P4: =M4*O4 -> 4526000 | Q4: =IFERROR(VLOOKUP(G4,SCENARIOS!$A$13:$E$18,2,0),0.025) -> 0.025 | R4: =IFERROR(VLOOKUP(L4,INPUTS!$A$107:$B$120,2,0),0.0082) -> 0.0079 | S4: =O4*R4 -> 48.98 | T4: =M4*S4 -> 35755.4 | U4: =T4/INPUTS!$B$7*1000 -> 44694250 | V4: =T4*INPUTS!$B$6 -> 112987.06 | W4: Yes | X4: Yes | Y4: =IFERROR(VLOOKUP(E4,INPUTS!$A$44:$B$103,2,0),0) -> 0.02 | Z4: =T4*Y4 -> 715.108 | AA4: =IFERROR(VLOOKUP(E4,INPUTS!$A$44:$C$103,3,0),SCENARIOS!$J$23) -> 0.06 | AB4: =$T4*AA4*(1+$Q4)^AB$2 -> 2427.2372 | AC4: =IFERROR(VLOOKUP($E4,INPUTS!$A$44:$G$103,4,0),SCENARIOS!$K$23) -> 0.15 | AD4: =$T4*AC4*(1+$Q4)^AD$2 -> 6865.4902 | AE4: =IFERROR(VLOOKUP($E4,INPUTS!$A$44:$G$103,5,0),SCENARIOS!$L$23) -> 0.3 | AF4: =$T4*AE4*(1+$Q4)^AF$2 -> 15535.344 | AG4: =IFERROR(VLOOKUP($E4,INPUTS!$A$44:$G$103,6,0),SCENARIOS!$M$23) -> 0.4 | AH4: =$T4*AG4*(1+$Q4)^AH$2 -> 23435.755 | AI4: =IFERROR(VLOOKUP($E4,INPUTS!$A$44:$G$103,7,0),SCENARIOS!$N$23) -> 0.5 | AJ4: =$T4*AI4*(1+$Q4)^AJ$2 -> 33144.256 | AL4: =IF(H4="MULTI","MULTI",IF(COUNTIFS($E$4:$E$1277,H4,$H$4:$H$1277,E4)>0,"Y","N")) -> N | AM4: =T4*((1+Q4)^25) -> 66288.513 | AT4: EU | AU4: =SUMIF($G$4:$G$1277,$AT4,$Z$4:$Z$1277) -> 761802.07 | AV4: =SUMIF($G$4:$G$1277,$AT4,$AB$4:$AB$1277) -> 3015007 | AW4: =SUMIF($G$4:$G$1277,$AT4,$AD$4:$AD$1277) -> 7313783 | AX4: =SUMIF($G$4:$G$1277,$AT4,$AF$4:$AF$1277) -> 16549748 | AY4: =SUMIF($G$4:$G$1277,$AT4,$AH$4:$AH$1277) -> 24966028 | AZ4: =SUMIF($G$4:$G$1277,$AT4,$AJ$4:$AJ$1277) -> 35308461 | BC4: {=_xlfn._xlws.SORT(_xlfn.UNIQUE(E$4:E$1277))} -> ABU | BD4: =SUMIF($E$4:$E$1277,$BC4,$Z$4:$Z$1277) -> 0 | BE4: =SUMIF($E$4:$E$1277,$BC4,$AB$4:$AB$1277) -> 0 | BF4: =SUMIF($E$4:$E$1277,$BC4,$AD$4:$AD$1277) -> 0 | BG4: =SUMIF($E$4:$E$1277,$BC4,$AF$4:$AF$1277) -> 0 | BH4: =SUMIF($E$4:$E$1277,$BC4,$AH$4:$AH$1277) -> 0 | BI4: =SUMIF($E$4:$E$1277,$BC4,$AJ$4:$AJ$1277) -> 0 | BM4: {=_xlfn._xlws.SORT(_xlfn.UNIQUE(F$4:F$1277))} -> Argentina | BN4: =SUMIF($F$4:$F$1277,$BM4,$Z$4:$Z$1277) -> 0 | BO4: =SUMIF($F$4:$F$1277,$BM4,$AB$4:$AB$1277) -> 0 | BP4: =SUMIF($F$4:$F$1277,$BM4,$AD$4:$AD$1277) -> 0 | BQ4: =SUMIF($F$4:$F$1277,$BM4,$AF$4:$AF$1277) -> 0 | BR4: =SUMIF($F$4:$F$1277,$BM4,$AH$4:$AH$1277) -> 0 | BS4: =SUMIF($F$4:$F$1277,$BM4,$AJ$4:$AJ$1277) -> 0
A5: R002 | B5: LH | C5: Lufthansa | D5: Passenger | E5: FRA | F5: Germany | G5: EU | H5: PEK | I5: China | J5: APAC | K5: international | L5: A350-900 | M5: 365 | N5: =M5/365 -> 1 | O5: 9200 | P5: =M5*O5 -> 3358000 | Q5: =IFERROR(VLOOKUP(G5,SCENARIOS!$A$13:$E$18,2,0),0.025) -> 0.025 | R5: =IFERROR(VLOOKUP(L5,INPUTS!$A$107:$B$120,2,0),0.0082) -> 0.0079 | S5: =O5*R5 -> 72.68 | T5: =M5*S5 -> 26528.2 | U5: =T5/INPUTS!$B$7*1000 -> 33160250 | V5: =T5*INPUTS!$B$6 -> 83829.112 | W5: No | X5: Yes | Y5: =IFERROR(VLOOKUP(E5,INPUTS!$A$44:$B$103,2,0),0) -> 0.02 | Z5: =T5*Y5 -> 530.564 | AA5: =IFERROR(VLOOKUP(E5,INPUTS!$A$44:$C$103,3,0),SCENARIOS!$J$23) -> 0.06 | AB5: =$T5*AA5*(1+$Q5)^AB$2 -> 1800.8534 | AC5: =IFERROR(VLOOKUP($E5,INPUTS!$A$44:$G$103,4,0),SCENARIOS!$K$23) -> 0.15 | AD5: =$T5*AC5*(1+$Q5)^AD$2 -> 5093.7508 | AE5: =IFERROR(VLOOKUP($E5,INPUTS!$A$44:$G$103,5,0),SCENARIOS!$L$23) -> 0.3 | AF5: =$T5*AE5*(1+$Q5)^AF$2 -> 11526.223 | AG5: =IFERROR(VLOOKUP($E5,INPUTS!$A$44:$G$103,6,0),SCENARIOS!$M$23) -> 0.4 | AH5: =$T5*AG5*(1+$Q5)^AH$2 -> 17387.818 | AI5: =IFERROR(VLOOKUP($E5,INPUTS!$A$44:$G$103,7,0),SCENARIOS!$N$23) -> 0.5 | AJ5: =$T5*AI5*(1+$Q5)^AJ$2 -> 24590.9 | AL5: =IF(H5="MULTI","MULTI",IF(COUNTIFS($E$4:$E$1277,H5,$H$4:$H$1277,E5)>0,"Y","N")) -> N | AM5: =T5*((1+Q5)^25) -> 49181.8 | AT5: US | AU5: =SUMIF($G$4:$G$1277,$AT5,$Z$4:$Z$1277) -> 22105.417 | AV5: =SUMIF($G$4:$G$1277,$AT5,$AB$4:$AB$1277) -> 146437 | AW5: =SUMIF($G$4:$G$1277,$AT5,$AD$4:$AD$1277) -> 538927.59 | AX5: =SUMIF($G$4:$G$1277,$AT5,$AF$4:$AF$1277) -> 1190039.2 | AY5: =SUMIF($G$4:$G$1277,$AT5,$AH$4:$AH$1277) -> 1970849.2 | AZ5: =SUMIF($G$4:$G$1277,$AT5,$AJ$4:$AJ$1277) -> 2901302.3 | BC5: ADD | BD5: =SUMIF($E$4:$E$1277,$BC5,$Z$4:$Z$1277) -> 0 | BE5: =SUMIF($E$4:$E$1277,$BC5,$AB$4:$AB$1277) -> 0 | BF5: =SUMIF($E$4:$E$1277,$BC5,$AD$4:$AD$1277) -> 0 | BG5: =SUMIF($E$4:$E$1277,$BC5,$AF$4:$AF$1277) -> 0 | BH5: =SUMIF($E$4:$E$1277,$BC5,$AH$4:$AH$1277) -> 0 | BI5: =SUMIF($E$4:$E$1277,$BC5,$AJ$4:$AJ$1277) -> 0 | BM5: Australia | BN5: =SUMIF($F$4:$F$1277,$BM5,$Z$4:$Z$1277) -> 0 | BO5: =SUMIF($F$4:$F$1277,$BM5,$AB$4:$AB$1277) -> 366002.9 | BP5: =SUMIF($F$4:$F$1277,$BM5,$AD$4:$AD$1277) -> 890596.99 | BQ5: =SUMIF($F$4:$F$1277,$BM5,$AF$4:$AF$1277) -> 2167094.8 | BR5: =SUMIF($F$4:$F$1277,$BM5,$AH$4:$AH$1277) -> 3954903.3 | BS5: =SUMIF($F$4:$F$1277,$BM5,$AJ$4:$AJ$1277) -> 6415659.5
A6: R003 | B6: LH | C6: Lufthansa | D6: Passenger | E6: FRA | F6: Germany | G6: EU | H6: DXB | I6: UAE | J6: MENA | K6: international | L6: B787-9 | M6: 730 | N6: =M6/365 -> 2 | O6: 5100 | P6: =M6*O6 -> 3723000 | Q6: =IFERROR(VLOOKUP(G6,SCENARIOS!$A$13:$E$18,2,0),0.025) -> 0.025 | R6: =IFERROR(VLOOKUP(L6,INPUTS!$A$107:$B$120,2,0),0.0082) -> 0.0079 | S6: =O6*R6 -> 40.29 | T6: =M6*S6 -> 29411.7 | U6: =T6/INPUTS!$B$7*1000 -> 36764625 | V6: =T6*INPUTS!$B$6 -> 92940.972 | W6: Yes | X6: Yes | Y6: =IFERROR(VLOOKUP(E6,INPUTS!$A$44:$B$103,2,0),0) -> 0.02 | Z6: =T6*Y6 -> 588.234 | AA6: =IFERROR(VLOOKUP(E6,INPUTS!$A$44:$C$103,3,0),SCENARIOS!$J$23) -> 0.06 | AB6: =$T6*AA6*(1+$Q6)^AB$2 -> 1996.5983 | AC6: =IFERROR(VLOOKUP($E6,INPUTS!$A$44:$G$103,4,0),SCENARIOS!$K$23) -> 0.15 | AD6: =$T6*AC6*(1+$Q6)^AD$2 -> 5647.4194 | AE6: =IFERROR(VLOOKUP($E6,INPUTS!$A$44:$G$103,5,0),SCENARIOS!$L$23) -> 0.3 | AF6: =$T6*AE6*(1+$Q6)^AF$2 -> 12779.073 | AG6: =IFERROR(VLOOKUP($E6,INPUTS!$A$44:$G$103,6,0),SCENARIOS!$M$23) -> 0.4 | AH6: =$T6*AG6*(1+$Q6)^AH$2 -> 19277.798 | AI6: =IFERROR(VLOOKUP($E6,INPUTS!$A$44:$G$103,7,0),SCENARIOS!$N$23) -> 0.5 | AJ6: =$T6*AI6*(1+$Q6)^AJ$2 -> 27263.824 | AL6: =IF(H6="MULTI","MULTI",IF(COUNTIFS($E$4:$E$1277,H6,$H$4:$H$1277,E6)>0,"Y","N")) -> Y | AM6: =T6*((1+Q6)^25) -> 54527.648 | AT6: APAC | AU6: =SUMIF($G$4:$G$1277,$AT6,$Z$4:$Z$1277) -> 0 | AV6: =SUMIF($G$4:$G$1277,$AT6,$AB$4:$AB$1277) -> 1197524.6 | AW6: =SUMIF($G$4:$G$1277,$AT6,$AD$4:$AD$1277) -> 2845899.3 | AX6: =SUMIF($G$4:$G$1277,$AT6,$AF$4:$AF$1277) -> 6974002 | AY6: =SUMIF($G$4:$G$1277,$AT6,$AH$4:$AH$1277) -> 12130968 | AZ6: =SUMIF($G$4:$G$1277,$AT6,$AJ$4:$AJ$1277) -> 19267748 | BC6: AKL | BD6: =SUMIF($E$4:$E$1277,$BC6,$Z$4:$Z$1277) -> 0 | BE6: =SUMIF($E$4:$E$1277,$BC6,$AB$4:$AB$1277) -> 13256.928 | BF6: =SUMIF($E$4:$E$1277,$BC6,$AD$4:$AD$1277) -> 40322.699 | BG6: =SUMIF($E$4:$E$1277,$BC6,$AF$4:$AF$1277) -> 147176.19 | BH6: =SUMIF($E$4:$E$1277,$BC6,$AH$4:$AH$1277) -> 238749.78 | BI6: =SUMIF($E$4:$E$1277,$BC6,$AJ$4:$AJ$1277) -> 435713.42 | BM6: Austria | BN6: =SUMIF($F$4:$F$1277,$BM6,$Z$4:$Z$1277) -> 39805.758 | BO6: =SUMIF($F$4:$F$1277,$BM6,$AB$4:$AB$1277) -> 135109.69 | BP6: =SUMIF($F$4:$F$1277,$BM6,$AD$4:$AD$1277) -> 382160.52 | BQ6: =SUMIF($F$4:$F$1277,$BM6,$AF$4:$AF$1277) -> 864759.1 | BR6: =SUMIF($F$4:$F$1277,$BM6,$AH$4:$AH$1277) -> 1304527.4 | BS6: =SUMIF($F$4:$F$1277,$BM6,$AJ$4:$AJ$1277) -> 1844941.3
A7: R004 | B7: LH | C7: Lufthansa | D7: Passenger | E7: FRA | F7: Germany | G7: EU | H7: SIN | I7: Singapore | J7: APAC | K7: international | L7: A350-900 | M7: 365 | N7: =M7/365 -> 1 | O7: 10600 | P7: =M7*O7 -> 3869000 | Q7: =IFERROR(VLOOKUP(G7,SCENARIOS!$A$13:$E$18,2,0),0.025) -> 0.025 | R7: =IFERROR(VLOOKUP(L7,INPUTS!$A$107:$B$120,2,0),0.0082) -> 0.0079 | S7: =O7*R7 -> 83.74 | T7: =M7*S7 -> 30565.1 | U7: =T7/INPUTS!$B$7*1000 -> 38206375 | V7: =T7*INPUTS!$B$6 -> 96585.716 | W7: Yes | X7: Yes | Y7: =IFERROR(VLOOKUP(E7,INPUTS!$A$44:$B$103,2,0),0) -> 0.02 | Z7: =T7*Y7 -> 611.302 | AA7: =IFERROR(VLOOKUP(E7,INPUTS!$A$44:$C$103,3,0),SCENARIOS!$J$23) -> 0.06 | AB7: =$T7*AA7*(1+$Q7)^AB$2 -> 2074.8963 | AC7: =IFERROR(VLOOKUP($E7,INPUTS!$A$44:$G$103,4,0),SCENARIOS!$K$23) -> 0.15 | AD7: =$T7*AC7*(1+$Q7)^AD$2 -> 5868.8868 | AE7: =IFERROR(VLOOKUP($E7,INPUTS!$A$44:$G$103,5,0),SCENARIOS!$L$23) -> 0.3 | AF7: =$T7*AE7*(1+$Q7)^AF$2 -> 13280.213 | AG7: =IFERROR(VLOOKUP($E7,INPUTS!$A$44:$G$103,6,0),SCENARIOS!$M$23) -> 0.4 | AH7: =$T7*AG7*(1+$Q7)^AH$2 -> 20033.79 | AI7: =IFERROR(VLOOKUP($E7,INPUTS!$A$44:$G$103,7,0),SCENARIOS!$N$23) -> 0.5 | AJ7: =$T7*AI7*(1+$Q7)^AJ$2 -> 28332.993 | AL7: =IF(H7="MULTI","MULTI",IF(COUNTIFS($E$4:$E$1277,H7,$H$4:$H$1277,E7)>0,"Y","N")) -> Y | AM7: =T7*((1+Q7)^25) -> 56665.987 | AT7: MENA | AU7: =SUMIF($G$4:$G$1277,$AT7,$Z$4:$Z$1277) -> 0 | AV7: =SUMIF($G$4:$G$1277,$AT7,$AB$4:$AB$1277) -> 0 | AW7: =SUMIF($G$4:$G$1277,$AT7,$AD$4:$AD$1277) -> 0 | AX7: =SUMIF($G$4:$G$1277,$AT7,$AF$4:$AF$1277) -> 0 | AY7: =SUMIF($G$4:$G$1277,$AT7,$AH$4:$AH$1277) -> 0 | AZ7: =SUMIF($G$4:$G$1277,$AT7,$AJ$4:$AJ$1277) -> 0 | BC7: AMM | BD7: =SUMIF($E$4:$E$1277,$BC7,$Z$4:$Z$1277) -> 0 | BE7: =SUMIF($E$4:$E$1277,$BC7,$AB$4:$AB$1277) -> 0 | BF7: =SUMIF($E$4:$E$1277,$BC7,$AD$4:$AD$1277) -> 0 | BG7: =SUMIF($E$4:$E$1277,$BC7,$AF$4:$AF$1277) -> 0 | BH7: =SUMIF($E$4:$E$1277,$BC7,$AH$4:$AH$1277) -> 0 | BI7: =SUMIF($E$4:$E$1277,$BC7,$AJ$4:$AJ$1277) -> 0 | BM7: Bahrain | BN7: =SUMIF($F$4:$F$1277,$BM7,$Z$4:$Z$1277) -> 0 | BO7: =SUMIF($F$4:$F$1277,$BM7,$AB$4:$AB$1277) -> 0 | BP7: =SUMIF($F$4:$F$1277,$BM7,$AD$4:$AD$1277) -> 0 | BQ7: =SUMIF($F$4:$F$1277,$BM7,$AF$4:$AF$1277) -> 0 | BR7: =SUMIF($F$4:$F$1277,$BM7,$AH$4:$AH$1277) -> 0 | BS7: =SUMIF($F$4:$F$1277,$BM7,$AJ$4:$AJ$1277) -> 0
A8: R005 | B8: AF | C8: Air France | D8: Passenger | E8: CDG | F8: France | G8: EU | H8: JFK | I8: United States | J8: US | K8: international | L8: B787-9 | M8: 730 | N8: =M8/365 -> 2 | O8: 5830 | P8: =M8*O8 -> 4255900 | Q8: =IFERROR(VLOOKUP(G8,SCENARIOS!$A$13:$E$18,2,0),0.025) -> 0.025 | R8: =IFERROR(VLOOKUP(L8,INPUTS!$A$107:$B$120,2,0),0.0082) -> 0.0079 | S8: =O8*R8 -> 46.057 | T8: =M8*S8 -> 33621.61 | U8: =T8/INPUTS!$B$7*1000 -> 42027012 | V8: =T8*INPUTS!$B$6 -> 106244.29 | W8: Yes | X8: Yes | Y8: =IFERROR(VLOOKUP(E8,INPUTS!$A$44:$B$103,2,0),0) -> 0.02 | Z8: =T8*Y8 -> 672.4322 | AA8: =IFERROR(VLOOKUP(E8,INPUTS!$A$44:$C$103,3,0),SCENARIOS!$J$23) -> 0.06 | AB8: =$T8*AA8*(1+$Q8)^AB$2 -> 2282.3859 | AC8: =IFERROR(VLOOKUP($E8,INPUTS!$A$44:$G$103,4,0),SCENARIOS!$K$23) -> 0.15 | AD8: =$T8*AC8*(1+$Q8)^AD$2 -> 6455.7755 | AE8: =IFERROR(VLOOKUP($E8,INPUTS!$A$44:$G$103,5,0),SCENARIOS!$L$23) -> 0.3 | AF8: =$T8*AE8*(1+$Q8)^AF$2 -> 14608.235 | AG8: =IFERROR(VLOOKUP($E8,INPUTS!$A$44:$G$103,6,0),SCENARIOS!$M$23) -> 0.4 | AH8: =$T8*AG8*(1+$Q8)^AH$2 -> 22037.169 | AI8: =IFERROR(VLOOKUP($E8,INPUTS!$A$44:$G$103,7,0),SCENARIOS!$N$23) -> 0.5 | AJ8: =$T8*AI8*(1+$Q8)^AJ$2 -> 31166.293 | AL8: =IF(H8="MULTI","MULTI",IF(COUNTIFS($E$4:$E$1277,H8,$H$4:$H$1277,E8)>0,"Y","N")) -> Y | AM8: =T8*((1+Q8)^25) -> 62332.585 | AT8: LATAM | AU8: =SUMIF($G$4:$G$1277,$AT8,$Z$4:$Z$1277) -> 0 | AV8: =SUMIF($G$4:$G$1277,$AT8,$AB$4:$AB$1277) -> 0 | AW8: =SUMIF($G$4:$G$1277,$AT8,$AD$4:$AD$1277) -> 0 | AX8: =SUMIF($G$4:$G$1277,$AT8,$AF$4:$AF$1277) -> 0 | AY8: =SUMIF($G$4:$G$1277,$AT8,$AH$4:$AH$1277) -> 0 | AZ8: =SUMIF($G$4:$G$1277,$AT8,$AJ$4:$AJ$1277) -> 0 | BC8: AMS | BD8: =SUMIF($E$4:$E$1277,$BC8,$Z$4:$Z$1277) -> 49783.248 | BE8: =SUMIF($E$4:$E$1277,$BC8,$AB$4:$AB$1277) -> 168975.53 | BF8: =SUMIF($E$4:$E$1277,$BC8,$AD$4:$AD$1277) -> 477950.75 | BG8: =SUMIF($E$4:$E$1277,$BC8,$AF$4:$AF$1277) -> 1081514.8 | BH8: =SUMIF($E$4:$E$1277,$BC8,$AH$4:$AH$1277) -> 1631513 | BI8: =SUMIF($E$4:$E$1277,$BC8,$AJ$4:$AJ$1277) -> 2307384 | BM8: Belgium | BN8: =SUMIF($F$4:$F$1277,$BM8,$Z$4:$Z$1277) -> 3959.6358 | BO8: =SUMIF($F$4:$F$1277,$BM8,$AB$4:$AB$1277) -> 13439.893 | BP8: =SUMIF($F$4:$F$1277,$BM8,$AD$4:$AD$1277) -> 38015.014 | BQ8: =SUMIF($F$4:$F$1277,$BM8,$AF$4:$AF$1277) -> 86020.999 | BR8: =SUMIF($F$4:$F$1277,$BM8,$AH$4:$AH$1277) -> 129766.49 | BS8: =SUMIF($F$4:$F$1277,$BM8,$AJ$4:$AJ$1277) -> 183523.59
A9: R006 | B9: AF | C9: Air France | D9: Passenger | E9: CDG | F9: France | G9: EU | H9: NRT | I9: Japan | J9: APAC | K9: international | L9: B777-300ER | M9: 365 | N9: =M9/365 -> 1 | O9: 9730 | P9: =M9*O9 -> 3551450 | Q9: =IFERROR(VLOOKUP(G9,SCENARIOS!$A$13:$E$18,2,0),0.025) -> 0.025 | R9: =IFERROR(VLOOKUP(L9,INPUTS!$A$107:$B$120,2,0),0.0082) -> 0.0089 | S9: =O9*R9 -> 86.597 | T9: =M9*S9 -> 31607.905 | U9: =T9/INPUTS!$B$7*1000 -> 39509881 | V9: =T9*INPUTS!$B$6 -> 99880.98 | W9: Yes | X9: Yes | Y9: =IFERROR(VLOOKUP(E9,INPUTS!$A$44:$B$103,2,0),0) -> 0.02 | Z9: =T9*Y9 -> 632.1581 | AA9: =IFERROR(VLOOKUP(E9,INPUTS!$A$44:$C$103,3,0),SCENARIOS!$J$23) -> 0.06 | AB9: =$T9*AA9*(1+$Q9)^AB$2 -> 2145.6866 | AC9: =IFERROR(VLOOKUP($E9,INPUTS!$A$44:$G$103,4,0),SCENARIOS!$K$23) -> 0.15 | AD9: =$T9*AC9*(1+$Q9)^AD$2 -> 6069.1186 | AE9: =IFERROR(VLOOKUP($E9,INPUTS!$A$44:$G$103,5,0),SCENARIOS!$L$23) -> 0.3 | AF9: =$T9*AE9*(1+$Q9)^AF$2 -> 13733.301 | AG9: =IFERROR(VLOOKUP($E9,INPUTS!$A$44:$G$103,6,0),SCENARIOS!$M$23) -> 0.4 | AH9: =$T9*AG9*(1+$Q9)^AH$2 -> 20717.293 | AI9: =IFERROR(VLOOKUP($E9,INPUTS!$A$44:$G$103,7,0),SCENARIOS!$N$23) -> 0.5 | AJ9: =$T9*AI9*(1+$Q9)^AJ$2 -> 29299.644 | AL9: =IF(H9="MULTI","MULTI",IF(COUNTIFS($E$4:$E$1277,H9,$H$4:$H$1277,E9)>0,"Y","N")) -> Y | AM9: =T9*((1+Q9)^25) -> 58599.289 | AT9: ROW | AU9: =SUMIF($G$4:$G$1277,$AT9,$Z$4:$Z$1277) -> 0 | AV9: =SUMIF($G$4:$G$1277,$AT9,$AB$4:$AB$1277) -> 0 | AW9: =SUMIF($G$4:$G$1277,$AT9,$AD$4:$AD$1277) -> 0 | AX9: =SUMIF($G$4:$G$1277,$AT9,$AF$4:$AF$1277) -> 0 | AY9: =SUMIF($G$4:$G$1277,$AT9,$AH$4:$AH$1277) -> 0 | AZ9: =SUMIF($G$4:$G$1277,$AT9,$AJ$4:$AJ$1277) -> 0 | BC9: ANC | BD9: =SUMIF($E$4:$E$1277,$BC9,$Z$4:$Z$1277) -> 197.976 | BE9: =SUMIF($E$4:$E$1277,$BC9,$AB$4:$AB$1277) -> 1311.489 | BF9: =SUMIF($E$4:$E$1277,$BC9,$AD$4:$AD$1277) -> 4826.6328 | BG9: =SUMIF($E$4:$E$1277,$BC9,$AF$4:$AF$1277) -> 10657.985 | BH9: =SUMIF($E$4:$E$1277,$BC9,$AH$4:$AH$1277) -> 17650.915 | BI9: =SUMIF($E$4:$E$1277,$BC9,$AJ$4:$AJ$1277) -> 25984.049 | BM9: Brazil | BN9: =SUMIF($F$4:$F$1277,$BM9,$Z$4:$Z$1277) -> 0 | BO9: =SUMIF($F$4:$F$1277,$BM9,$AB$4:$AB$1277) -> 0 | BP9: =SUMIF($F$4:$F$1277,$BM9,$AD$4:$AD$1277) -> 0 | BQ9: =SUMIF($F$4:$F$1277,$BM9,$AF$4:$AF$1277) -> 0 | BR9: =SUMIF($F$4:$F$1277,$BM9,$AH$4:$AH$1277) -> 0 | BS9: =SUMIF($F$4:$F$1277,$BM9,$AJ$4:$AJ$1277) -> 0
A10: R007 | B10: BA | C10: British Airways | D10: Passenger | E10: LHR | F10: United Kingdom | G10: EU | H10: JFK | I10: United States | J10: US | K10: international | L10: B777-300ER | M10: 1460 | N10: =M10/365 -> 4 | O10: 5555 | P10: =M10*O10 -> 8110300 | Q10: =IFERROR(VLOOKUP(G10,SCENARIOS!$A$13:$E$18,2,0),0.025) -> 0.025 | R10: =IFERROR(VLOOKUP(L10,INPUTS!$A$107:$B$120,2,0),0.0082) -> 0.0089 | S10: =O10*R10 -> 49.4395 | T10: =M10*S10 -> 72181.67 | U10: =T10/INPUTS!$B$7*1000 -> 90227088 | V10: =T10*INPUTS!$B$6 -> 228094.08 | W10: Yes | X10: Yes | Y10: =IFERROR(VLOOKUP(E10,INPUTS!$A$44:$B$103,2,0),0) -> 0.02 | Z10: =T10*Y10 -> 1443.6334 | AA10: =IFERROR(VLOOKUP(E10,INPUTS!$A$44:$C$103,3,0),SCENARIOS!$J$23) -> 0.1 | AB10: =$T10*AA10*(1+$Q10)^AB$2 -> 8166.6934 | AC10: =IFERROR(VLOOKUP($E10,INPUTS!$A$44:$G$103,4,0),SCENARIOS!$K$23) -> 0.15 | AD10: =$T10*AC10*(1+$Q10)^AD$2 -> 13859.796 | AE10: =IFERROR(VLOOKUP($E10,INPUTS!$A$44:$G$103,5,0),SCENARIOS!$L$23) -> 0.3 | AF10: =$T10*AE10*(1+$Q10)^AF$2 -> 31362.174 | AG10: =IFERROR(VLOOKUP($E10,INPUTS!$A$44:$G$103,6,0),SCENARIOS!$M$23) -> 0.4 | AH10: =$T10*AG10*(1+$Q10)^AH$2 -> 47311.228 | AI10: =IFERROR(VLOOKUP($E10,INPUTS!$A$44:$G$103,7,0),SCENARIOS!$N$23) -> 0.5 | AJ10: =$T10*AI10*(1+$Q10)^AJ$2 -> 66910.391 | AL10: =IF(H10="MULTI","MULTI",IF(COUNTIFS($E$4:$E$1277,H10,$H$4:$H$1277,E10)>0,"Y","N")) -> Y | AM10: =T10*((1+Q10)^25) -> 133820.78 | BC10: ARN | BD10: =SUMIF($E$4:$E$1277,$BC10,$Z$4:$Z$1277) -> 0 | BE10: =SUMIF($E$4:$E$1277,$BC10,$AB$4:$AB$1277) -> 0 | BF10: =SUMIF($E$4:$E$1277,$BC10,$AD$4:$AD$1277) -> 0 | BG10: =SUMIF($E$4:$E$1277,$BC10,$AF$4:$AF$1277) -> 0 | BH10: =SUMIF($E$4:$E$1277,$BC10,$AH$4:$AH$1277) -> 0 | BI10: =SUMIF($E$4:$E$1277,$BC10,$AJ$4:$AJ$1277) -> 0 | BM10: Canada | BN10: =SUMIF($F$4:$F$1277,$BM10,$Z$4:$Z$1277) -> 0 | BO10: =SUMIF($F$4:$F$1277,$BM10,$AB$4:$AB$1277) -> 0 | BP10: =SUMIF($F$4:$F$1277,$BM10,$AD$4:$AD$1277) -> 0 | BQ10: =SUMIF($F$4:$F$1277,$BM10,$AF$4:$AF$1277) -> 0 | BR10: =SUMIF($F$4:$F$1277,$BM10,$AH$4:$AH$1277) -> 0 | BS10: =SUMIF($F$4:$F$1277,$BM10,$AJ$4:$AJ$1277) -> 0
A11: R008 | B11: BA | C11: British Airways | D11: Passenger | E11: LHR | F11: United Kingdom | G11: EU | H11: DXB | I11: UAE | J11: MENA | K11: international | L11: B777-300ER | M11: 1460 | N11: =M11/365 -> 4 | O11: 5490 | P11: =M11*O11 -> 8015400 | Q11: =IFERROR(VLOOKUP(G11,SCENARIOS!$A$13:$E$18,2,0),0.025) -> 0.025 | R11: =IFERROR(VLOOKUP(L11,INPUTS!$A$107:$B$120,2,0),0.0082) -> 0.0089 | S11: =O11*R11 -> 48.861 | T11: =M11*S11 -> 71337.06 | U11: =T11/INPUTS!$B$7*1000 -> 89171325 | V11: =T11*INPUTS!$B$6 -> 225425.11 | W11: Yes | X11: Yes | Y11: =IFERROR(VLOOKUP(E11,INPUTS!$A$44:$B$103,2,0),0) -> 0.02 | Z11: =T11*Y11 -> 1426.7412 | AA11: =IFERROR(VLOOKUP(E11,INPUTS!$A$44:$C$103,3,0),SCENARIOS!$J$23) -> 0.1 | AB11: =$T11*AA11*(1+$Q11)^AB$2 -> 8071.1336 | AC11: =IFERROR(VLOOKUP($E11,INPUTS!$A$44:$G$103,4,0),SCENARIOS!$K$23) -> 0.15 | AD11: =$T11*AC11*(1+$Q11)^AD$2 -> 13697.62 | AE11: =IFERROR(VLOOKUP($E11,INPUTS!$A$44:$G$103,5,0),SCENARIOS!$L$23) -> 0.3 | AF11: =$T11*AE11*(1+$Q11)^AF$2 -> 30995.2 | AG11: =IFERROR(VLOOKUP($E11,INPUTS!$A$44:$G$103,6,0),SCENARIOS!$M$23) -> 0.4 | AH11: =$T11*AG11*(1+$Q11)^AH$2 -> 46757.632 | AI11: =IFERROR(VLOOKUP($E11,INPUTS!$A$44:$G$103,7,0),SCENARIOS!$N$23) -> 0.5 | AJ11: =$T11*AI11*(1+$Q11)^AJ$2 -> 66127.461 | AL11: =IF(H11="MULTI","MULTI",IF(COUNTIFS($E$4:$E$1277,H11,$H$4:$H$1277,E11)>0,"Y","N")) -> Y | AM11: =T11*((1+Q11)^25) -> 132254.92 | AT11: Total | AU11: =SUM(AU4:AU9) -> 783907.49 | AV11: =SUM(AV4:AV9) -> 4358968.6 | AW11: =SUM(AW4:AW9) -> 10698610 | AX11: =SUM(AX4:AX9) -> 24713789 | AY11: =SUM(AY4:AY9) -> 39067846 | AZ11: =SUM(AZ4:AZ9) -> 57477512 | BC11: ATH | BD11: =SUMIF($E$4:$E$1277,$BC11,$Z$4:$Z$1277) -> 2623.5186 | BE11: =SUMIF($E$4:$E$1277,$BC11,$AB$4:$AB$1277) -> 8904.8115 | BF11: =SUMIF($E$4:$E$1277,$BC11,$AD$4:$AD$1277) -> 25187.442 | BG11: =SUMIF($E$4:$E$1277,$BC11,$AF$4:$AF$1277) -> 56994.558 | BH11: =SUMIF($E$4:$E$1277,$BC11,$AH$4:$AH$1277) -> 85978.814 | BI11: =SUMIF($E$4:$E$1277,$BC11,$AJ$4:$AJ$1277) -> 121596.42 | BM11: Chile | BN11: =SUMIF($F$4:$F$1277,$BM11,$Z$4:$Z$1277) -> 0 | BO11: =SUMIF($F$4:$F$1277,$BM11,$AB$4:$AB$1277) -> 0 | BP11: =SUMIF($F$4:$F$1277,$BM11,$AD$4:$AD$1277) -> 0 | BQ11: =SUMIF($F$4:$F$1277,$BM11,$AF$4:$AF$1277) -> 0 | BR11: =SUMIF($F$4:$F$1277,$BM11,$AH$4:$AH$1277) -> 0 | BS11: =SUMIF($F$4:$F$1277,$BM11,$AJ$4:$AJ$1277) -> 0
A12: R009 | B12: BA | C12: British Airways | D12: Passenger | E12: LHR | F12: United Kingdom | G12: EU | H12: HKG | I12: Hong Kong | J12: APAC | K12: international | L12: B777-300ER | M12: 730 | N12: =M12/365 -> 2 | O12: 9630 | P12: =M12*O12 -> 7029900 | Q12: =IFERROR(VLOOKUP(G12,SCENARIOS!$A$13:$E$18,2,0),0.025) -> 0.025 | R12: =IFERROR(VLOOKUP(L12,INPUTS!$A$107:$B$120,2,0),0.0082) -> 0.0089 | S12: =O12*R12 -> 85.707 | T12: =M12*S12 -> 62566.11 | U12: =T12/INPUTS!$B$7*1000 -> 78207638 | V12: =T12*INPUTS!$B$6 -> 197708.91 | W12: Yes | X12: Yes | Y12: =IFERROR(VLOOKUP(E12,INPUTS!$A$44:$B$103,2,0),0) -> 0.02 | Z12: =T12*Y12 -> 1251.3222 | AA12: =IFERROR(VLOOKUP(E12,INPUTS!$A$44:$C$103,3,0),SCENARIOS!$J$23) -> 0.1 | AB12: =$T12*AA12*(1+$Q12)^AB$2 -> 7078.7811 | AC12: =IFERROR(VLOOKUP($E12,INPUTS!$A$44:$G$103,4,0),SCENARIOS!$K$23) -> 0.15 | AD12: =$T12*AC12*(1+$Q12)^AD$2 -> 12013.487 | AE12: =IFERROR(VLOOKUP($E12,INPUTS!$A$44:$G$103,5,0),SCENARIOS!$L$23) -> 0.3 | AF12: =$T12*AE12*(1+$Q12)^AF$2 -> 27184.315 | AG12: =IFERROR(VLOOKUP($E12,INPUTS!$A$44:$G$103,6,0),SCENARIOS!$M$23) -> 0.4 | AH12: =$T12*AG12*(1+$Q12)^AH$2 -> 41008.743 | AI12: =IFERROR(VLOOKUP($E12,INPUTS!$A$44:$G$103,7,0),SCENARIOS!$N$23) -> 0.5 | AJ12: =$T12*AI12*(1+$Q12)^AJ$2 -> 57997.035 | AL12: =IF(H12="MULTI","MULTI",IF(COUNTIFS($E$4:$E$1277,H12,$H$4:$H$1277,E12)>0,"Y","N")) -> Y | AM12: =T12*((1+Q12)^25) -> 115994.07 | BC12: ATL | BD12: =SUMIF($E$4:$E$1277,$BC12,$Z$4:$Z$1277) -> 923.47238 | BE12: =SUMIF($E$4:$E$1277,$BC12,$AB$4:$AB$1277) -> 6117.5287 | BF12: =SUMIF($E$4:$E$1277,$BC12,$AD$4:$AD$1277) -> 22514.153 | BG12: =SUMIF($E$4:$E$1277,$BC12,$AF$4:$AF$1277) -> 49714.889 | BH12: =SUMIF($E$4:$E$1277,$BC12,$AH$4:$AH$1277) -> 82333.882 | BI12: =SUMIF($E$4:$E$1277,$BC12,$AJ$4:$AJ$1277) -> 121204.35 | BM12: China | BN12: =SUMIF($F$4:$F$1277,$BM12,$Z$4:$Z$1277) -> 0 | BO12: =SUMIF($F$4:$F$1277,$BM12,$AB$4:$AB$1277) -> 0 | BP12: =SUMIF($F$4:$F$1277,$BM12,$AD$4:$AD$1277) -> 0 | BQ12: =SUMIF($F$4:$F$1277,$BM12,$AF$4:$AF$1277) -> 0 | BR12: =SUMIF($F$4:$F$1277,$BM12,$AH$4:$AH$1277) -> 0 | BS12: =SUMIF($F$4:$F$1277,$BM12,$AJ$4:$AJ$1277) -> 0
A13: R010 | B13: BA | C13: British Airways | D13: Passenger | E13: LHR | F13: United Kingdom | G13: EU | H13: SYD | I13: Australia | J13: APAC | K13: international | L13: B787-9 | M13: 365 | N13: =M13/365 -> 1 | O13: 16990 | P13: =M13*O13 -> 6201350 | Q13: =IFERROR(VLOOKUP(G13,SCENARIOS!$A$13:$E$18,2,0),0.025) -> 0.025 | R13: =IFERROR(VLOOKUP(L13,INPUTS!$A$107:$B$120,2,0),0.0082) -> 0.0079 | S13: =O13*R13 -> 134.221 | T13: =M13*S13 -> 48990.665 | U13: =T13/INPUTS!$B$7*1000 -> 61238331 | V13: =T13*INPUTS!$B$6 -> 154810.5 | W13: Yes | X13: Yes | Y13: =IFERROR(VLOOKUP(E13,INPUTS!$A$44:$B$103,2,0),0) -> 0.02 | Z13: =T13*Y13 -> 979.8133 | AA13: =IFERROR(VLOOKUP(E13,INPUTS!$A$44:$C$103,3,0),SCENARIOS!$J$23) -> 0.1 | AB13: =$T13*AA13*(1+$Q13)^AB$2 -> 5542.8441 | AC13: =IFERROR(VLOOKUP($E13,INPUTS!$A$44:$G$103,4,0),SCENARIOS!$K$23) -> 0.15 | AD13: =$T13*AC13*(1+$Q13)^AD$2 -> 9406.829 | AE13: =IFERROR(VLOOKUP($E13,INPUTS!$A$44:$G$103,5,0),SCENARIOS!$L$23) -> 0.3 | AF13: =$T13*AE13*(1+$Q13)^AF$2 -> 21285.927 | AG13: =IFERROR(VLOOKUP($E13,INPUTS!$A$44:$G$103,6,0),SCENARIOS!$M$23) -> 0.4 | AH13: =$T13*AG13*(1+$Q13)^AH$2 -> 32110.764 | AI13: =IFERROR(VLOOKUP($E13,INPUTS!$A$44:$G$103,7,0),SCENARIOS!$N$23) -> 0.5 | AJ13: =$T13*AI13*(1+$Q13)^AJ$2 -> 45412.977 | AL13: =IF(H13="MULTI","MULTI",IF(COUNTIFS($E$4:$E$1277,H13,$H$4:$H$1277,E13)>0,"Y","N")) -> Y | AM13: =T13*((1+Q13)^25) -> 90825.954 | BC13: AUH | BD13: =SUMIF($E$4:$E$1277,$BC13,$Z$4:$Z$1277) -> 0 | BE13: =SUMIF($E$4:$E$1277,$BC13,$AB$4:$AB$1277) -> 0 | BF13: =SUMIF($E$4:$E$1277,$BC13,$AD$4:$AD$1277) -> 0 | BG13: =SUMIF($E$4:$E$1277,$BC13,$AF$4:$AF$1277) -> 0 | BH13: =SUMIF($E$4:$E$1277,$BC13,$AH$4:$AH$1277) -> 0 | BI13: =SUMIF($E$4:$E$1277,$BC13,$AJ$4:$AJ$1277) -> 0 | BM13: Colombia | BN13: =SUMIF($F$4:$F$1277,$BM13,$Z$4:$Z$1277) -> 0 | BO13: =SUMIF($F$4:$F$1277,$BM13,$AB$4:$AB$1277) -> 0 | BP13: =SUMIF($F$4:$F$1277,$BM13,$AD$4:$AD$1277) -> 0 | BQ13: =SUMIF($F$4:$F$1277,$BM13,$AF$4:$AF$1277) -> 0 | BR13: =SUMIF($F$4:$F$1277,$BM13,$AH$4:$AH$1277) -> 0 | BS13: =SUMIF($F$4:$F$1277,$BM13,$AJ$4:$AJ$1277) -> 0
A14: R011 | B14: KL | C14: KLM | D14: Passenger | E14: AMS | F14: Netherlands | G14: EU | H14: GRU | I14: Brazil | J14: LATAM | K14: international | L14: B787-9 | M14: 365 | N14: =M14/365 -> 1 | O14: 9980 | P14: =M14*O14 -> 3642700 | Q14: =IFERROR(VLOOKUP(G14,SCENARIOS!$A$13:$E$18,2,0),0.025) -> 0.025 | R14: =IFERROR(VLOOKUP(L14,INPUTS!$A$107:$B$120,2,0),0.0082) -> 0.0079 | S14: =O14*R14 -> 78.842 | T14: =M14*S14 -> 28777.33 | U14: =T14/INPUTS!$B$7*1000 -> 35971662 | V14: =T14*INPUTS!$B$6 -> 90936.363 | W14: Yes | X14: Yes | Y14: =IFERROR(VLOOKUP(E14,INPUTS!$A$44:$B$103,2,0),0) -> 0.02 | Z14: =T14*Y14 -> 575.5466 | AA14: =IFERROR(VLOOKUP(E14,INPUTS!$A$44:$C$103,3,0),SCENARIOS!$J$23) -> 0.06 | AB14: =$T14*AA14*(1+$Q14)^AB$2 -> 1953.5345 | AC14: =IFERROR(VLOOKUP($E14,INPUTS!$A$44:$G$103,4,0),SCENARIOS!$K$23) -> 0.15 | AD14: =$T14*AC14*(1+$Q14)^AD$2 -> 5525.6123 | AE14: =IFERROR(VLOOKUP($E14,INPUTS!$A$44:$G$103,5,0),SCENARIOS!$L$23) -> 0.3 | AF14: =$T14*AE14*(1+$Q14)^AF$2 -> 12503.446 | AG14: =IFERROR(VLOOKUP($E14,INPUTS!$A$44:$G$103,6,0),SCENARIOS!$M$23) -> 0.4 | AH14: =$T14*AG14*(1+$Q14)^AH$2 -> 18862.002 | AI14: =IFERROR(VLOOKUP($E14,INPUTS!$A$44:$G$103,7,0),SCENARIOS!$N$23) -> 0.5 | AJ14: =$T14*AI14*(1+$Q14)^AJ$2 -> 26675.781 | AL14: =IF(H14="MULTI","MULTI",IF(COUNTIFS($E$4:$E$1277,H14,$H$4:$H$1277,E14)>0,"Y","N")) -> N | AM14: =T14*((1+Q14)^25) -> 53351.561 | AT14: SAF in million tonnes per annum | BC14: BAH | BD14: =SUMIF($E$4:$E$1277,$BC14,$Z$4:$Z$1277) -> 0 | BE14: =SUMIF($E$4:$E$1277,$BC14,$AB$4:$AB$1277) -> 0 | BF14: =SUMIF($E$4:$E$1277,$BC14,$AD$4:$AD$1277) -> 0 | BG14: =SUMIF($E$4:$E$1277,$BC14,$AF$4:$AF$1277) -> 0 | BH14: =SUMIF($E$4:$E$1277,$BC14,$AH$4:$AH$1277) -> 0 | BI14: =SUMIF($E$4:$E$1277,$BC14,$AJ$4:$AJ$1277) -> 0 | BM14: Czechia | BN14: =SUMIF($F$4:$F$1277,$BM14,$Z$4:$Z$1277) -> 0 | BO14: =SUMIF($F$4:$F$1277,$BM14,$AB$4:$AB$1277) -> 0 | BP14: =SUMIF($F$4:$F$1277,$BM14,$AD$4:$AD$1277) -> 0 | BQ14: =SUMIF($F$4:$F$1277,$BM14,$AF$4:$AF$1277) -> 0 | BR14: =SUMIF($F$4:$F$1277,$BM14,$AH$4:$AH$1277) -> 0 | BS14: =SUMIF($F$4:$F$1277,$BM14,$AJ$4:$AJ$1277) -> 0
A15: R012 | B15: IB | C15: Iberia | D15: Passenger | E15: MAD | F15: Spain | G15: EU | H15: GRU | I15: Brazil | J15: LATAM | K15: international | L15: A350-900 | M15: 730 | N15: =M15/365 -> 2 | O15: 10000 | P15: =M15*O15 -> 7300000 | Q15: =IFERROR(VLOOKUP(G15,SCENARIOS!$A$13:$E$18,2,0),0.025) -> 0.025 | R15: =IFERROR(VLOOKUP(L15,INPUTS!$A$107:$B$120,2,0),0.0082) -> 0.0079 | S15: =O15*R15 -> 79 | T15: =M15*S15 -> 57670 | U15: =T15/INPUTS!$B$7*1000 -> 72087500 | V15: =T15*INPUTS!$B$6 -> 182237.2 | W15: Yes | X15: Yes | Y15: =IFERROR(VLOOKUP(E15,INPUTS!$A$44:$B$103,2,0),0) -> 0.02 | Z15: =T15*Y15 -> 1153.4 | AA15: =IFERROR(VLOOKUP(E15,INPUTS!$A$44:$C$103,3,0),SCENARIOS!$J$23) -> 0.06 | AB15: =$T15*AA15*(1+$Q15)^AB$2 -> 3914.8987 | AC15: =IFERROR(VLOOKUP($E15,INPUTS!$A$44:$G$103,4,0),SCENARIOS!$K$23) -> 0.15 | AD15: =$T15*AC15*(1+$Q15)^AD$2 -> 11073.371 | AE15: =IFERROR(VLOOKUP($E15,INPUTS!$A$44:$G$103,5,0),SCENARIOS!$L$23) -> 0.3 | AF15: =$T15*AE15*(1+$Q15)^AF$2 -> 25057.007 | AG15: =IFERROR(VLOOKUP($E15,INPUTS!$A$44:$G$103,6,0),SCENARIOS!$M$23) -> 0.4 | AH15: =$T15*AG15*(1+$Q15)^AH$2 -> 37799.604 | AI15: =IFERROR(VLOOKUP($E15,INPUTS!$A$44:$G$103,7,0),SCENARIOS!$N$23) -> 0.5 | AJ15: =$T15*AI15*(1+$Q15)^AJ$2 -> 53458.478 | AL15: =IF(H15="MULTI","MULTI",IF(COUNTIFS($E$4:$E$1277,H15,$H$4:$H$1277,E15)>0,"Y","N")) -> Y | AM15: =T15*((1+Q15)^25) -> 106916.96 | BC15: BCN | BD15: =SUMIF($E$4:$E$1277,$BC15,$Z$4:$Z$1277) -> 27991.031 | BE15: =SUMIF($E$4:$E$1277,$BC15,$AB$4:$AB$1277) -> 95007.847 | BF15: =SUMIF($E$4:$E$1277,$BC15,$AD$4:$AD$1277) -> 268731.65 | BG15: =SUMIF($E$4:$E$1277,$BC15,$AF$4:$AF$1277) -> 608090.38 | BH15: =SUMIF($E$4:$E$1277,$BC15,$AH$4:$AH$1277) -> 917331.27 | BI15: =SUMIF($E$4:$E$1277,$BC15,$AJ$4:$AJ$1277) -> 1297345.2 | BM15: Denmark | BN15: =SUMIF($F$4:$F$1277,$BM15,$Z$4:$Z$1277) -> 40816.131 | BO15: =SUMIF($F$4:$F$1277,$BM15,$AB$4:$AB$1277) -> 138539.12 | BP15: =SUMIF($F$4:$F$1277,$BM15,$AD$4:$AD$1277) -> 391860.74 | BQ15: =SUMIF($F$4:$F$1277,$BM15,$AF$4:$AF$1277) -> 886708.91 | BR15: =SUMIF($F$4:$F$1277,$BM15,$AH$4:$AH$1277) -> 1337639.7 | BS15: =SUMIF($F$4:$F$1277,$BM15,$AJ$4:$AJ$1277) -> 1891770.6
A16: R013 | B16: LH | C16: Lufthansa | D16: Passenger | E16: FRA | F16: Germany | G16: EU | H16: CDG | I16: France | J16: EU | K16: international | L16: A320neo | M16: 3650 | N16: =M16/365 -> 10 | O16: 480 | P16: =M16*O16 -> 1752000 | Q16: =IFERROR(VLOOKUP(G16,SCENARIOS!$A$13:$E$18,2,0),0.025) -> 0.025 | R16: =IFERROR(VLOOKUP(L16,INPUTS!$A$107:$B$120,2,0),0.0082) -> 0.0039 | S16: =O16*R16 -> 1.872 | T16: =M16*S16 -> 6832.8 | U16: =T16/INPUTS!$B$7*1000 -> 8541000 | V16: =T16*INPUTS!$B$6 -> 21591.648 | W16: Yes | X16: Yes | Y16: =IFERROR(VLOOKUP(E16,INPUTS!$A$44:$B$103,2,0),0) -> 0.02 | Z16: =T16*Y16 -> 136.656 | AA16: =IFERROR(VLOOKUP(E16,INPUTS!$A$44:$C$103,3,0),SCENARIOS!$J$23) -> 0.06 | AB16: =$T16*AA16*(1+$Q16)^AB$2 -> 463.84116 | AC16: =IFERROR(VLOOKUP($E16,INPUTS!$A$44:$G$103,4,0),SCENARIOS!$K$23) -> 0.15 | AD16: =$T16*AC16*(1+$Q16)^AD$2 -> 1311.9843 | AE16: =IFERROR(VLOOKUP($E16,INPUTS!$A$44:$G$103,5,0),SCENARIOS!$L$23) -> 0.3 | AF16: =$T16*AE16*(1+$Q16)^AF$2 -> 2968.7795 | AG16: =IFERROR(VLOOKUP($E16,INPUTS!$A$44:$G$103,6,0),SCENARIOS!$M$23) -> 0.4 | AH16: =$T16*AG16*(1+$Q16)^AH$2 -> 4478.5354 | AI16: =IFERROR(VLOOKUP($E16,INPUTS!$A$44:$G$103,7,0),SCENARIOS!$N$23) -> 0.5 | AJ16: =$T16*AI16*(1+$Q16)^AJ$2 -> 6333.8146 | AL16: =IF(H16="MULTI","MULTI",IF(COUNTIFS($E$4:$E$1277,H16,$H$4:$H$1277,E16)>0,"Y","N")) -> N | AM16: =T16*((1+Q16)^25) -> 12667.629 | AT16: EU | AU16: =AU4/1000000 -> 0.76180207 | AV16: =AV4/1000000 -> 3.015007 | AW16: =AW4/1000000 -> 7.313783 | AX16: =AX4/1000000 -> 16.549748 | AY16: =AY4/1000000 -> 24.966028 | AZ16: =AZ4/1000000 -> 35.308461 | BC16: BGY | BD16: =SUMIF($E$4:$E$1277,$BC16,$Z$4:$Z$1277) -> 0 | BE16: =SUMIF($E$4:$E$1277,$BC16,$AB$4:$AB$1277) -> 0 | BF16: =SUMIF($E$4:$E$1277,$BC16,$AD$4:$AD$1277) -> 0 | BG16: =SUMIF($E$4:$E$1277,$BC16,$AF$4:$AF$1277) -> 0 | BH16: =SUMIF($E$4:$E$1277,$BC16,$AH$4:$AH$1277) -> 0 | BI16: =SUMIF($E$4:$E$1277,$BC16,$AJ$4:$AJ$1277) -> 0 | BM16: Egypt | BN16: =SUMIF($F$4:$F$1277,$BM16,$Z$4:$Z$1277) -> 0 | BO16: =SUMIF($F$4:$F$1277,$BM16,$AB$4:$AB$1277) -> 0 | BP16: =SUMIF($F$4:$F$1277,$BM16,$AD$4:$AD$1277) -> 0 | BQ16: =SUMIF($F$4:$F$1277,$BM16,$AF$4:$AF$1277) -> 0 | BR16: =SUMIF($F$4:$F$1277,$BM16,$AH$4:$AH$1277) -> 0 | BS16: =SUMIF($F$4:$F$1277,$BM16,$AJ$4:$AJ$1277) -> 0
A17: R014 | B17: BA | C17: British Airways | D17: Passenger | E17: LHR | F17: United Kingdom | G17: EU | H17: AMS | I17: Netherlands | J17: EU | K17: international | L17: A320neo | M17: 3650 | N17: =M17/365 -> 10 | O17: 370 | P17: =M17*O17 -> 1350500 | Q17: =IFERROR(VLOOKUP(G17,SCENARIOS!$A$13:$E$18,2,0),0.025) -> 0.025 | R17: =IFERROR(VLOOKUP(L17,INPUTS!$A$107:$B$120,2,0),0.0082) -> 0.0039 | S17: =O17*R17 -> 1.443 | T17: =M17*S17 -> 5266.95 | U17: =T17/INPUTS!$B$7*1000 -> 6583687.5 | V17: =T17*INPUTS!$B$6 -> 16643.562 | W17: Yes | X17: Yes | Y17: =IFERROR(VLOOKUP(E17,INPUTS!$A$44:$B$103,2,0),0) -> 0.02 | Z17: =T17*Y17 -> 105.339 | AA17: =IFERROR(VLOOKUP(E17,INPUTS!$A$44:$C$103,3,0),SCENARIOS!$J$23) -> 0.1 | AB17: =$T17*AA17*(1+$Q17)^AB$2 -> 595.90705 | AC17: =IFERROR(VLOOKUP($E17,INPUTS!$A$44:$G$103,4,0),SCENARIOS!$K$23) -> 0.15 | AD17: =$T17*AC17*(1+$Q17)^AD$2 -> 1011.3212 | AE17: =IFERROR(VLOOKUP($E17,INPUTS!$A$44:$G$103,5,0),SCENARIOS!$L$23) -> 0.3 | AF17: =$T17*AE17*(1+$Q17)^AF$2 -> 2288.4342 | AG17: =IFERROR(VLOOKUP($E17,INPUTS!$A$44:$G$103,6,0),SCENARIOS!$M$23) -> 0.4 | AH17: =$T17*AG17*(1+$Q17)^AH$2 -> 3452.2043 | AI17: =IFERROR(VLOOKUP($E17,INPUTS!$A$44:$G$103,7,0),SCENARIOS!$N$23) -> 0.5 | AJ17: =$T17*AI17*(1+$Q17)^AJ$2 -> 4882.3154 | AL17: =IF(H17="MULTI","MULTI",IF(COUNTIFS($E$4:$E$1277,H17,$H$4:$H$1277,E17)>0,"Y","N")) -> N | AM17: =T17*((1+Q17)^25) -> 9764.6309 | AT17: US | AU17: =AU5/1000000 -> 0.022105417 | AV17: =AV5/1000000 -> 0.146437 | AW17: =AW5/1000000 -> 0.53892759 | AX17: =AX5/1000000 -> 1.1900392 | AY17: =AY5/1000000 -> 1.9708492 | AZ17: =AZ5/1000000 -> 2.9013023 | BC17: BKK | BD17: =SUMIF($E$4:$E$1277,$BC17,$Z$4:$Z$1277) -> 0 | BE17: =SUMIF($E$4:$E$1277,$BC17,$AB$4:$AB$1277) -> 0 | BF17: =SUMIF($E$4:$E$1277,$BC17,$AD$4:$AD$1277) -> 0 | BG17: =SUMIF($E$4:$E$1277,$BC17,$AF$4:$AF$1277) -> 0 | BH17: =SUMIF($E$4:$E$1277,$BC17,$AH$4:$AH$1277) -> 0 | BI17: =SUMIF($E$4:$E$1277,$BC17,$AJ$4:$AJ$1277) -> 0 | BM17: Ethiopia | BN17: =SUMIF($F$4:$F$1277,$BM17,$Z$4:$Z$1277) -> 0 | BO17: =SUMIF($F$4:$F$1277,$BM17,$AB$4:$AB$1277) -> 0 | BP17: =SUMIF($F$4:$F$1277,$BM17,$AD$4:$AD$1277) -> 0 | BQ17: =SUMIF($F$4:$F$1277,$BM17,$AF$4:$AF$1277) -> 0 | BR17: =SUMIF($F$4:$F$1277,$BM17,$AH$4:$AH$1277) -> 0 | BS17: =SUMIF($F$4:$F$1277,$BM17,$AJ$4:$AJ$1277) -> 0
A18: R015 | AT18: APAC | AU18: =AU6/1000000 -> 0 | AV18: =AV6/1000000 -> 1.1975246 | AW18: =AW6/1000000 -> 2.8458993 | AX18: =AX6/1000000 -> 6.974002 | AY18: =AY6/1000000 -> 12.130968 | AZ18: =AZ6/1000000 -> 19.267748 | BC18: BOG | BD18: =SUMIF($E$4:$E$1277,$BC18,$Z$4:$Z$1277) -> 0 | BE18: =SUMIF($E$4:$E$1277,$BC18,$AB$4:$AB$1277) -> 0 | BF18: =SUMIF($E$4:$E$1277,$BC18,$AD$4:$AD$1277) -> 0 | BG18: =SUMIF($E$4:$E$1277,$BC18,$AF$4:$AF$1277) -> 0 | BH18: =SUMIF($E$4:$E$1277,$BC18,$AH$4:$AH$1277) -> 0 | BI18: =SUMIF($E$4:$E$1277,$BC18,$AJ$4:$AJ$1277) -> 0 | BM18: Finland | BN18: =SUMIF($F$4:$F$1277,$BM18,$Z$4:$Z$1277) -> 44270.503 | BO18: =SUMIF($F$4:$F$1277,$BM18,$AB$4:$AB$1277) -> 150264.03 | BP18: =SUMIF($F$4:$F$1277,$BM18,$AD$4:$AD$1277) -> 425024.9 | BQ18: =SUMIF($F$4:$F$1277,$BM18,$AF$4:$AF$1277) -> 961753.33 | BR18: =SUMIF($F$4:$F$1277,$BM18,$AH$4:$AH$1277) -> 1450847.5 | BS18: =SUMIF($F$4:$F$1277,$BM18,$AJ$4:$AJ$1277) -> 2051876
A19: R016 | AT19: MENA | AU19: =AU7/1000000 -> 0 | AV19: =AV7/1000000 -> 0 | AW19: =AW7/1000000 -> 0 | AX19: =AX7/1000000 -> 0 | AY19: =AY7/1000000 -> 0 | AZ19: =AZ7/1000000 -> 0 | BC19: BOM | BD19: =SUMIF($E$4:$E$1277,$BC19,$Z$4:$Z$1277) -> 0 | BE19: =SUMIF($E$4:$E$1277,$BC19,$AB$4:$AB$1277) -> 0 | BF19: =SUMIF($E$4:$E$1277,$BC19,$AD$4:$AD$1277) -> 0 | BG19: =SUMIF($E$4:$E$1277,$BC19,$AF$4:$AF$1277) -> 0 | BH19: =SUMIF($E$4:$E$1277,$BC19,$AH$4:$AH$1277) -> 0 | BI19: =SUMIF($E$4:$E$1277,$BC19,$AJ$4:$AJ$1277) -> 0 | BM19: France | BN19: =SUMIF($F$4:$F$1277,$BM19,$Z$4:$Z$1277) -> 44677.704 | BO19: =SUMIF($F$4:$F$1277,$BM19,$AB$4:$AB$1277) -> 151646.16 | BP19: =SUMIF($F$4:$F$1277,$BM19,$AD$4:$AD$1277) -> 428934.29 | BQ19: =SUMIF($F$4:$F$1277,$BM19,$AF$4:$AF$1277) -> 970599.55 | BR19: =SUMIF($F$4:$F$1277,$BM19,$AH$4:$AH$1277) -> 1464192.4 | BS19: =SUMIF($F$4:$F$1277,$BM19,$AJ$4:$AJ$1277) -> 2070749.1
